Workbook

Sheet Revenue Detail
A1: Revenue Detail — FY2027 Budget vs. Actual (by Month, Region, Product Line)
A3: Month | B3: Region | C3: Product Line | D3: Budgeted Units | E3: Budgeted Unit Price | F3: Budgeted Revenue | G3: Actual Units | H3: Actual Unit Price | I3: Actual Revenue | J3: Variance $ | K3: Variance % | L3: Month # | M3: Sales Channel | N3: YTD Actual Revenue | O3: % of FY Budget Achieved (YTD) | P3: Notes
A4: Jan | B4: Northeast | C4: Apparel | D4: 1804 | E4: 45 | F4: =D4*E4 -> 81180 | G4: 1872 | H4: 44.16 | I4: =G4*H4 -> 82667.52 | J4: =I4-F4 -> 1487.52 | K4: =IFERROR(J4/F4,0) -> 0.018323725 | L4: 1 | M4: Retail Stores | N4: =SUMIFS($I$4:$I$195,$B$4:$B$195,B4,$C$4:$C$195,C4,$L$4:$L$195,"<="&L4) -> 82667.52 | O4: =IFERROR(N4/SUMIFS($F$4:$F$195,$B$4:$B$195,B4,$C$4:$C$195,C4),0) -> 0.064515293
A5: Jan | B5: Northeast | C5: Home Goods | D5: 1082 | E5: 65 | F5: =D5*E5 -> 70330 | G5: 1033 | H5: 66.09 | I5: =G5*H5 -> 68270.97 | J5: =I5-F5 -> -2059.03 | K5: =IFERROR(J5/F5,0) -> -0.029276696 | L5: 1 | M5: E-Commerce | N5: =SUMIFS($I$4:$I$195,$B$4:$B$195,B5,$C$4:$C$195,C5,$L$4:$L$195,"<="&L5) -> 68270.97 | O5: =IFERROR(N5/SUMIFS($F$4:$F$195,$B$4:$B$195,B5,$C$4:$C$195,C5),0) -> 0.061476387
A6: Jan | B6: Northeast | C6: Electronics | D6: 451 | E6: 220 | F6: =D6*E6 -> 99220 | G6: 491 | H6: 216.56 | I6: =G6*H6 -> 106330.96 | J6: =I6-F6 -> 7110.96 | K6: =IFERROR(J6/F6,0) -> 0.071668615 | L6: 1 | M6: Retail Stores | N6: =SUMIFS($I$4:$I$195,$B$4:$B$195,B6,$C$4:$C$195,C6,$L$4:$L$195,"<="&L6) -> 106330.96 | O6: =IFERROR(N6/SUMIFS($F$4:$F$195,$B$4:$B$195,B6,$C$4:$C$195,C6),0) -> 0.067888435
A7: Jan | B7: Northeast | C7: Outdoor | D7: 722 | E7: 95 | F7: =D7*E7 -> 68590 | G7: 661 | H7: 94.14 | I7: =G7*H7 -> 62226.54 | J7: =I7-F7 -> -6363.46 | K7: =IFERROR(J7/F7,0) -> -0.092775332 | L7: 1 | M7: E-Commerce | N7: =SUMIFS($I$4:$I$195,$B$4:$B$195,B7,$C$4:$C$195,C7,$L$4:$L$195,"<="&L7) -> 62226.54 | O7: =IFERROR(N7/SUMIFS($F$4:$F$195,$B$4:$B$195,B7,$C$4:$C$195,C7),0) -> 0.05750787
A8: Jan | B8: Midwest | C8: Apparel | D8: 1443 | E8: 45 | F8: =D8*E8 -> 64935 | G8: 1321 | H8: 44.55 | I8: =G8*H8 -> 58850.55 | J8: =I8-F8 -> -6084.45 | K8: =IFERROR(J8/F8,0) -> -0.093700624 | L8: 1 | M8: E-Commerce | N8: =SUMIFS($I$4:$I$195,$B$4:$B$195,B8,$C$4:$C$195,C8,$L$4:$L$195,"<="&L8) -> 58850.55 | O8: =IFERROR(N8/SUMIFS($F$4:$F$195,$B$4:$B$195,B8,$C$4:$C$195,C8),0) -> 0.057410085
A9: Jan | B9: Midwest | C9: Home Goods | D9: 866 | E9: 65 | F9: =D9*E9 -> 56290 | G9: 882 | H9: 64.42 | I9: =G9*H9 -> 56818.44 | J9: =I9-F9 -> 528.44 | K9: =IFERROR(J9/F9,0) -> 0.0093878131 | L9: 1 | M9: E-Commerce | N9: =SUMIFS($I$4:$I$195,$B$4:$B$195,B9,$C$4:$C$195,C9,$L$4:$L$195,"<="&L9) -> 56818.44 | O9: =IFERROR(N9/SUMIFS($F$4:$F$195,$B$4:$B$195,B9,$C$4:$C$195,C9),0) -> 0.06395456
A10: Jan | B10: Midwest | C10: Electronics | D10: 361 | E10: 220 | F10: =D10*E10 -> 79420 | G10: 387 | H10: 215.67 | I10: =G10*H10 -> 83464.29 | J10: =I10-F10 -> 4044.29 | K10: =IFERROR(J10/F10,0) -> 0.050922815 | L10: 1 | M10: E-Commerce | N10: =SUMIFS($I$4:$I$195,$B$4:$B$195,B10,$C$4:$C$195,C10,$L$4:$L$195,"<="&L10) -> 83464.29 | O10: =IFERROR(N10/SUMIFS($F$4:$F$195,$B$4:$B$195,B10,$C$4:$C$195,C10),0) -> 0.066615828
A11: Jan | B11: Midwest | C11: Outdoor | D11: 577 | E11: 95 | F11: =D11*E11 -> 54815 | G11: 606 | H11: 94.72 | I11: =G11*H11 -> 57400.32 | J11: =I11-F11 -> 2585.32 | K11: =IFERROR(J11/F11,0) -> 0.047164462 | L11: 1 | M11: Retail Stores | N11: =SUMIFS($I$4:$I$195,$B$4:$B$195,B11,$C$4:$C$195,C11,$L$4:$L$195,"<="&L11) -> 57400.32 | O11: =IFERROR(N11/SUMIFS($F$4:$F$195,$B$4:$B$195,B11,$C$4:$C$195,C11),0) -> 0.066316907
A12: Jan | B12: South | C12: Apparel | D12: 1640 | E12: 45 | F12: =D12*E12 -> 73800 | G12: 1806 | H12: 44.86 | I12: =G12*H12 -> 81017.16 | J12: =I12-F12 -> 7217.16 | K12: =IFERROR(J12/F12,0) -> 0.097793496 | L12: 1 | M12: Retail Stores | N12: =SUMIFS($I$4:$I$195,$B$4:$B$195,B12,$C$4:$C$195,C12,$L$4:$L$195,"<="&L12) -> 81017.16 | O12: =IFERROR(N12/SUMIFS($F$4:$F$195,$B$4:$B$195,B12,$C$4:$C$195,C12),0) -> 0.069550053
A13: Jan | B13: South | C13: Home Goods | D13: 984 | E13: 65 | F13: =D13*E13 -> 63960 | G13: 914 | H13: 66.45 | I13: =G13*H13 -> 60735.3 | J13: =I13-F13 -> -3224.7 | K13: =IFERROR(J13/F13,0) -> -0.050417448 | L13: 1 | M13: E-Commerce | N13: =SUMIFS($I$4:$I$195,$B$4:$B$195,B13,$C$4:$C$195,C13,$L$4:$L$195,"<="&L13) -> 60735.3 | O13: =IFERROR(N13/SUMIFS($F$4:$F$195,$B$4:$B$195,B13,$C$4:$C$195,C13),0) -> 0.060159754
A14: Jan | B14: South | C14: Electronics | D14: 410 | E14: 220 | F14: =D14*E14 -> 90200 | G14: 439 | H14: 223.63 | I14: =G14*H14 -> 98173.57 | J14: =I14-F14 -> 7973.57 | K14: =IFERROR(J14/F14,0) -> 0.08839878 | L14: 1 | M14: E-Commerce | N14: =SUMIFS($I$4:$I$195,$B$4:$B$195,B14,$C$4:$C$195,C14,$L$4:$L$195,"<="&L14) -> 98173.57 | O14: =IFERROR(N14/SUMIFS($F$4:$F$195,$B$4:$B$195,B14,$C$4:$C$195,C14),0) -> 0.068953057
A15: Jan | B15: South | C15: Outdoor | D15: 656 | E15: 95 | F15: =D15*E15 -> 62320 | G15: 725 | H15: 94.9 | I15: =G15*H15 -> 68802.5 | J15: =I15-F15 -> 6482.5 | K15: =IFERROR(J15/F15,0) -> 0.10401958 | L15: 1 | M15: E-Commerce | N15: =SUMIFS($I$4:$I$195,$B$4:$B$195,B15,$C$4:$C$195,C15,$L$4:$L$195,"<="&L15) -> 68802.5 | O15: =IFERROR(N15/SUMIFS($F$4:$F$195,$B$4:$B$195,B15,$C$4:$C$195,C15),0) -> 0.069943707
... A23: Feb | B23: Northeast | C23: Outdoor | D23: 739 | E23: 95.24 | F23: =D23*E23 -> 70382.36 | G23: 780 | H23: 94.11 | I23: =G23*H23 -> 73405.8 | J23: =I23-F23 -> 3023.44 | K23: =IFERROR(J23/F23,0) -> 0.042957355 | L23: 2 | M23: Retail Stores | N23: =SUMIFS($I$4:$I$195,$B$4:$B$195,B23,$C$4:$C$195,C23,$L$4:$L$195,"<="&L23) -> 135632.34 | O23: =IFERROR(N23/SUMIFS($F$4:$F$195,$B$4:$B$195,B23,$C$4:$C$195,C23),0) -> 0.12534727
A24: Feb | B24: Midwest | C24: Apparel | D24: 1478 | E24: 45.11 | F24: =D24*E24 -> 66672.58 | G24: 1637 | H24: 45.65 | I24: =G24*H24 -> 74729.05 | J24: =I24-F24 -> 8056.47 | K24: =IFERROR(J24/F24,0) -> 0.12083633 | L24: 2 | M24: E-Commerce | N24: =SUMIFS($I$4:$I$195,$B$4:$B$195,B24,$C$4:$C$195,C24,$L$4:$L$195,"<="&L24) -> 133579.6 | O24: =IFERROR(N24/SUMIFS($F$4:$F$195,$B$4:$B$195,B24,$C$4:$C$195,C24),0) -> 0.13031002 | P24: Promotional lift exceeded expectations for this line.
A25: Feb | B25: Midwest | C25: Home Goods | D25: 887 | E25: 65.16 | F25: =D25*E25 -> 57796.92 | G25: 865 | H25: 66.36 | I25: =G25*H25 -> 57401.4 | J25: =I25-F25 -> -395.52 | K25: =IFERROR(J25/F25,0) -> -0.0068432712 | L25: 2 | M25: Retail Stores | N25: =SUMIFS($I$4:$I$195,$B$4:$B$195,B25,$C$4:$C$195,C25,$L$4:$L$195,"<="&L25) -> 114219.84 | O25: =IFERROR(N25/SUMIFS($F$4:$F$195,$B$4:$B$195,B25,$C$4:$C$195,C25),0) -> 0.1285653
A26: Feb | B26: Midwest | C26: Electronics | D26: 370 | E26: 220.55 | F26: =D26*E26 -> 81603.5 | G26: 398 | H26: 225.02 | I26: =G26*H26 -> 89557.96 | J26: =I26-F26 -> 7954.46 | K26: =IFERROR(J26/F26,0) -> 0.097476946 | L26: 2 | M26: Retail Stores | N26: =SUMIFS($I$4:$I$195,$B$4:$B$195,B26,$C$4:$C$195,C26,$L$4:$L$195,"<="&L26) -> 173022.25 | O26: =IFERROR(N26/SUMIFS($F$4:$F$195,$B$4:$B$195,B26,$C$4:$C$195,C26),0) -> 0.13809523
A27: Feb | B27: Midwest | C27: Outdoor | D27: 591 | E27: 95.24 | F27: =D27*E27 -> 56286.84 | G27: 546 | H27: 97.68 | I27: =G27*H27 -> 53333.28 | J27: =I27-F27 -> -2953.56 | K27: =IFERROR(J27/F27,0) -> -0.052473367 | L27: 2 | M27: E-Commerce | N27: =SUMIFS($I$4:$I$195,$B$4:$B$195,B27,$C$4:$C$195,C27,$L$4:$L$195,"<="&L27) -> 110733.6 | O27: =IFERROR(N27/SUMIFS($F$4:$F$195,$B$4:$B$195,B27,$C$4:$C$195,C27),0) -> 0.127935
A28: Feb | B28: South | C28: Apparel | D28: 1680 | E28: 45.11 | F28: =D28*E28 -> 75784.8 | G28: 1770 | H28: 44.69 | I28: =G28*H28 -> 79101.3 | J28: =I28-F28 -> 3316.5 | K28: =IFERROR(J28/F28,0) -> 0.043762074 | L28: 2 | M28: E-Commerce | N28: =SUMIFS($I$4:$I$195,$B$4:$B$195,B28,$C$4:$C$195,C28,$L$4:$L$195,"<="&L28) -> 160118.46 | O28: =IFERROR(N28/SUMIFS($F$4:$F$195,$B$4:$B$195,B28,$C$4:$C$195,C28),0) -> 0.13745542
A29: Feb | B29: South | C29: Home Goods | D29: 1008 | E29: 65.16 | F29: =D29*E29 -> 65681.28 | G29: 1096 | H29: 65.95 | I29: =G29*H29 -> 72281.2 | J29: =I29-F29 -> 6599.92 | K29: =IFERROR(J29/F29,0) -> 0.10048403 | L29: 2 | M29: Retail Stores | N29: =SUMIFS($I$4:$I$195,$B$4:$B$195,B29,$C$4:$C$195,C29,$L$4:$L$195,"<="&L29) -> 133016.5 | O29: =IFERROR(N29/SUMIFS($F$4:$F$195,$B$4:$B$195,B29,$C$4:$C$195,C29),0) -> 0.131756
A30: Feb | B30: South | C30: Electronics | D30: 420 | E30: 220.55 | F30: =D30*E30 -> 92631 | G30: 394 | H30: 224.35 | I30: =G30*H30 -> 88393.9 | J30: =I30-F30 -> -4237.1 | K30: =IFERROR(J30/F30,0) -> -0.045741706 | L30: 2 | M30: E-Commerce | N30: =SUMIFS($I$4:$I$195,$B$4:$B$195,B30,$C$4:$C$195,C30,$L$4:$L$195,"<="&L30) -> 186567.47 | O30: =IFERROR(N30/SUMIFS($F$4:$F$195,$B$4:$B$195,B30,$C$4:$C$195,C30),0) -> 0.13103728
A31: Feb | B31: South | C31: Outdoor | D31: 672 | E31: 95.24 | F31: =D31*E31 -> 64001.28 | G31: 712 | H31: 95.38 | I31: =G31*H31 -> 67910.56 | J31: =I31-F31 -> 3909.28 | K31: =IFERROR(J31/F31,0) -> 0.061081278 | L31: 2 | M31: E-Commerce | N31: =SUMIFS($I$4:$I$195,$B$4:$B$195,B31,$C$4:$C$195,C31,$L$4:$L$195,"<="&L31) -> 136713.06 | O31: =IFERROR(N31/SUMIFS($F$4:$F$195,$B$4:$B$195,B31,$C$4:$C$195,C31),0) -> 0.13898068
A32: Feb | B32: West | C32: Apparel | D32: 1982 | E32: 45.11 | F32: =D32*E32 -> 89408.02 | G32: 1947 | H32: 46.46 | I32: =G32*H32 -> 90457.62 | J32: =I32-F32 -> 1049.6 | K32: =IFERROR(J32/F32,0) -> 0.011739439 | L32: 2 | M32: Retail Stores | N32: =SUMIFS($I$4:$I$195,$B$4:$B$195,B32,$C$4:$C$195,C32,$L$4:$L$195,"<="&L32) -> 185167.8 | O32: =IFERROR(N32/SUMIFS($F$4:$F$195,$B$4:$B$195,B32,$C$4:$C$195,C32),0) -> 0.13471124
A33: Feb | B33: West | C33: Home Goods | D33: 1189 | E33: 65.16 | F33: =D33*E33 -> 77475.24 | G33: 1199 | H33: 66.32 | I33: =G33*H33 -> 79517.68 | J33: =I33-F33 -> 2042.44 | K33: =IFERROR(J33/F33,0) -> 0.026362487 | L33: 2 | M33: Wholesale | N33: =SUMIFS($I$4:$I$195,$B$4:$B$195,B33,$C$4:$C$195,C33,$L$4:$L$195,"<="&L33) -> 158111.77 | O33: =IFERROR(N33/SUMIFS($F$4:$F$195,$B$4:$B$195,B33,$C$4:$C$195,C33),0) -> 0.13272323
A34: Feb | B34: West | C34: Electronics | D34: 496 | E34: 220.55 | F34: =D34*E34 -> 109392.8 | G34: 467 | H34: 217.9 | I34: =G34*H34 -> 101759.3 | J34: =I34-F34 -> -7633.5 | K34: =IFERROR(J34/F34,0) -> -0.069780644 | L34: 2 | M34: E-Commerce | N34: =SUMIFS($I$4:$I$195,$B$4:$B$195,B34,$C$4:$C$195,C34,$L$4:$L$195,"<="&L34) -> 203054.44 | O34: =IFERROR(N34/SUMIFS($F$4:$F$195,$B$4:$B$195,B34,$C$4:$C$195,C34),0) -> 0.12085416
A35: Feb | B35: West | C35: Outdoor | D35: 793 | E35: 95.24 | F35: =D35*E35 -> 75525.32 | G35: 816 | H35: 95.17 | I35: =G35*H35 -> 77658.72 | J35: =I35-F35 -> 2133.4 | K35: =IFERROR(J35/F35,0) -> 0.02824748 | L35: 2 | M35: E-Commerce | N35: =SUMIFS($I$4:$I$195,$B$4:$B$195,B35,$C$4:$C$195,C35,$L$4:$L$195,"<="&L35) -> 146907.92 | O35: =IFERROR(N35/SUMIFS($F$4:$F$195,$B$4:$B$195,B35,$C$4:$C$195,C35),0) -> 0.12656325
A36: Mar | B36: Northeast | C36: Apparel | D36: 2046 | E36: 45.22 | F36: =D36*E36 -> 92520.12 | G36: 2053 | H36: 44.88 | I36: =G36*H36 -> 92138.64 | J36: =I36-F36 -> -381.48 | K36: =IFERROR(J36/F36,0) -> -0.0041232113 | L36: 3 | M36: E-Commerce | N36: =SUMIFS($I$4:$I$195,$B$4:$B$195,B36,$C$4:$C$195,C36,$L$4:$L$195,"<="&L36) -> 261128.67 | O36: =IFERROR(N36/SUMIFS($F$4:$F$195,$B$4:$B$195,B36,$C$4:$C$195,C36),0) -> 0.20378974
... A40: Mar | B40: Midwest | C40: Apparel | D40: 1637 | E40: 45.22 | F40: =D40*E40 -> 74025.14 | G40: 1491 | H40: 45.95 | I40: =G40*H40 -> 68511.45 | J40: =I40-F40 -> -5513.69 | K40: =IFERROR(J40/F40,0) -> -0.07448402 | L40: 3 | M40: E-Commerce | N40: =SUMIFS($I$4:$I$195,$B$4:$B$195,B40,$C$4:$C$195,C40,$L$4:$L$195,"<="&L40) -> 202091.05 | O40: =IFERROR(N40/SUMIFS($F$4:$F$195,$B$4:$B$195,B40,$C$4:$C$195,C40),0) -> 0.19714454
A41: Mar | B41: Midwest | C41: Home Goods | D41: 982 | E41: 65.32 | F41: =D41*E41 -> 64144.24 | G41: 1084 | H41: 66.5 | I41: =G41*H41 -> 72086 | J41: =I41-F41 -> 7941.76 | K41: =IFERROR(J41/F41,0) -> 0.12381096 | L41: 3 | M41: E-Commerce | N41: =SUMIFS($I$4:$I$195,$B$4:$B$195,B41,$C$4:$C$195,C41,$L$4:$L$195,"<="&L41) -> 186305.84 | O41: =IFERROR(N41/SUMIFS($F$4:$F$195,$B$4:$B$195,B41,$C$4:$C$195,C41),0) -> 0.20970495 | P41: Strong sell-through; consider raising next year's unit forecast.
A42: Mar | B42: Midwest | C42: Electronics | D42: 409 | E42: 221.1 | F42: =D42*E42 -> 90429.9 | G42: 443 | H42: 219.98 | I42: =G42*H42 -> 97451.14 | J42: =I42-F42 -> 7021.24 | K42: =IFERROR(J42/F42,0) -> 0.077642904 | L42: 3 | M42: E-Commerce | N42: =SUMIFS($I$4:$I$195,$B$4:$B$195,B42,$C$4:$C$195,C42,$L$4:$L$195,"<="&L42) -> 270473.39 | O42: =IFERROR(N42/SUMIFS($F$4:$F$195,$B$4:$B$195,B42,$C$4:$C$195,C42),0) -> 0.21587446
A43: Mar | B43: Midwest | C43: Outdoor | D43: 655 | E43: 95.47 | F43: =D43*E43 -> 62532.85 | G43: 676 | H43: 94.29 | I43: =G43*H43 -> 63740.04 | J43: =I43-F43 -> 1207.19 | K43: =IFERROR(J43/F43,0) -> 0.019304893 | L43: 3 | M43: E-Commerce | N43: =SUMIFS($I$4:$I$195,$B$4:$B$195,B43,$C$4:$C$195,C43,$L$4:$L$195,"<="&L43) -> 174473.64 | O43: =IFERROR(N43/SUMIFS($F$4:$F$195,$B$4:$B$195,B43,$C$4:$C$195,C43),0) -> 0.20157644
A44: Mar | B44: South | C44: Apparel | D44: 1860 | E44: 45.22 | F44: =D44*E44 -> 84109.2 | G44: 1893 | H44: 46.08 | I44: =G44*H44 -> 87229.44 | J44: =I44-F44 -> 3120.24 | K44: =IFERROR(J44/F44,0) -> 0.037097488 | L44: 3 | M44: E-Commerce | N44: =SUMIFS($I$4:$I$195,$B$4:$B$195,B44,$C$4:$C$195,C44,$L$4:$L$195,"<="&L44) -> 247347.9 | O44: =IFERROR(N44/SUMIFS($F$4:$F$195,$B$4:$B$195,B44,$C$4:$C$195,C44),0) -> 0.21233847
A45: Mar | B45: South | C45: Home Goods | D45: 1116 | E45: 65.32 | F45: =D45*E45 -> 72897.12 | G45: 1016 | H45: 65.07 | I45: =G45*H45 -> 66111.12 | J45: =I45-F45 -> -6786 | K45: =IFERROR(J45/F45,0) -> -0.093090097 | L45: 3 | M45: Retail Stores | N45: =SUMIFS($I$4:$I$195,$B$4:$B$195,B45,$C$4:$C$195,C45,$L$4:$L$195,"<="&L45) -> 199127.62 | O45: =IFERROR(N45/SUMIFS($F$4:$F$195,$B$4:$B$195,B45,$C$4:$C$195,C45),0) -> 0.19724063
A46: Mar | B46: South | C46: Electronics | D46: 465 | E46: 221.1 | F46: =D46*E46 -> 102811.5 | G46: 510 | H46: 226.39 | I46: =G46*H46 -> 115458.9 | J46: =I46-F46 -> 12647.4 | K46: =IFERROR(J46/F46,0) -> 0.12301542 | L46: 3 | M46: E-Commerce | N46: =SUMIFS($I$4:$I$195,$B$4:$B$195,B46,$C$4:$C$195,C46,$L$4:$L$195,"<="&L46) -> 302026.37 | O46: =IFERROR(N46/SUMIFS($F$4:$F$195,$B$4:$B$195,B46,$C$4:$C$195,C46),0) -> 0.21213084 | P46: Outperformed plan on unexpected demand; monitor inventory levels.
A47: Mar | B47: South | C47: Outdoor | D47: 744 | E47: 95.47 | F47: =D47*E47 -> 71029.68 | G47: 713 | H47: 94.71 | I47: =G47*H47 -> 67528.23 | J47: =I47-F47 -> -3501.45 | K47: =IFERROR(J47/F47,0) -> -0.04929559 | L47: 3 | M47: E-Commerce | N47: =SUMIFS($I$4:$I$195,$B$4:$B$195,B47,$C$4:$C$195,C47,$L$4:$L$195,"<="&L47) -> 204241.29 | O47: =IFERROR(N47/SUMIFS($F$4:$F$195,$B$4:$B$195,B47,$C$4:$C$195,C47),0) -> 0.20762898
A48: Mar | B48: West | C48: Apparel | D48: 2195 | E48: 45.22 | F48: =D48*E48 -> 99257.9 | G48: 2032 | H48: 45.97 | I48: =G48*H48 -> 93411.04 | J48: =I48-F48 -> -5846.86 | K48: =IFERROR(J48/F48,0) -> -0.058905739 | L48: 3 | M48: E-Commerce | N48: =SUMIFS($I$4:$I$195,$B$4:$B$195,B48,$C$4:$C$195,C48,$L$4:$L$195,"<="&L48) -> 278578.84 | O48: =IFERROR(N48/SUMIFS($F$4:$F$195,$B$4:$B$195,B48,$C$4:$C$195,C48),0) -> 0.20266861
A49: Mar | B49: West | C49: Home Goods | D49: 1317 | E49: 65.32 | F49: =D49*E49 -> 86026.44 | G49: 1456 | H49: 65.75 | I49: =G49*H49 -> 95732 | J49: =I49-F49 -> 9705.56 | K49: =IFERROR(J49/F49,0) -> 0.11282066 | L49: 3 | M49: Retail Stores | N49: =SUMIFS($I$4:$I$195,$B$4:$B$195,B49,$C$4:$C$195,C49,$L$4:$L$195,"<="&L49) -> 253843.77 | O49: =IFERROR(N49/SUMIFS($F$4:$F$195,$B$4:$B$195,B49,$C$4:$C$195,C49),0) -> 0.21308321
A50: Mar | B50: West | C50: Electronics | D50: 549 | E50: 221.1 | F50: =D50*E50 -> 121383.9 | G50: 572 | H50: 227.15 | I50: =G50*H50 -> 129929.8 | J50: =I50-F50 -> 8545.9 | K50: =IFERROR(J50/F50,0) -> 0.0704039 | L50: 3 | M50: Retail Stores | N50: =SUMIFS($I$4:$I$195,$B$4:$B$195,B50,$C$4:$C$195,C50,$L$4:$L$195,"<="&L50) -> 332984.24 | O50: =IFERROR(N50/SUMIFS($F$4:$F$195,$B$4:$B$195,B50,$C$4:$C$195,C50),0) -> 0.19818592
A51: Mar | B51: West | C51: Outdoor | D51: 878 | E51: 95.47 | F51: =D51*E51 -> 83822.66 | G51: 892 | H51: 96.46 | I51: =G51*H51 -> 86042.32 | J51: =I51-F51 -> 2219.66 | K51: =IFERROR(J51/F51,0) -> 0.026480429 | L51: 3 | M51: Wholesale | N51: =SUMIFS($I$4:$I$195,$B$4:$B$195,B51,$C$4:$C$195,C51,$L$4:$L$195,"<="&L51) -> 232950.24 | O51: =IFERROR(N51/SUMIFS($F$4:$F$195,$B$4:$B$195,B51,$C$4:$C$195,C51),0) -> 0.20068992
...

Sheet Expense Detail
A1: Expense Detail — FY2027 Budget vs. Actual (by Month, Department)
A3: Month | B3: Department | C3: Budgeted Amount | D3: Actual Amount | E3: Variance $ | F3: Variance % | G3: Expense Category | H3: Cost Center Code | I3: Month # | J3: YTD Actual Amount | K3: % of Annual Budget Used | L3: Notes
A4: Jan | B4: Sales | C4: 180000 | D4: 173595 | E4: =D4-C4 -> -6405 | F4: =IFERROR(E4/C4,0) -> -0.035583333 | G4: Payroll | H4: CC-1000 | I4: 1 | J4: =SUMIFS($D$4:$D$99,$B$4:$B$99,B4,$I$4:$I$99,"<="&I4) -> 173595 | K4: =IFERROR(J4/SUMIFS($C$4:$C$99,$B$4:$B$99,B4),0) -> 0.079192054
A5: Jan | B5: Marketing | C5: 150000 | D5: 165662 | E5: =D5-C5 -> 15662 | F5: =IFERROR(E5/C5,0) -> 0.10441333 | G5: Marketing Spend | H5: CC-2000 | I5: 1 | J5: =SUMIFS($D$4:$D$99,$B$4:$B$99,B5,$I$4:$I$99,"<="&I5) -> 165662 | K5: =IFERROR(J5/SUMIFS($C$4:$C$99,$B$4:$B$99,B5),0) -> 0.084282471 | L5: Overspend driven by higher contractor/vendor usage this month.
A6: Jan | B6: Operations | C6: 241120 | D6: 233149 | E6: =D6-C6 -> -7971 | F6: =IFERROR(E6/C6,0) -> -0.033058228 | G6: Payroll | H6: CC-3000 | I6: 1 | J6: =SUMIFS($D$4:$D$99,$B$4:$B$99,B6,$I$4:$I$99,"<="&I6) -> 233149 | K6: =IFERROR(J6/SUMIFS($C$4:$C$99,$B$4:$B$99,B6),0) -> 0.07442646
A7: Jan | B7: IT | C7: 95000 | D7: 95778 | E7: =D7-C7 -> 778 | F7: =IFERROR(E7/C7,0) -> 0.0081894737 | G7: Software & IT | H7: CC-4400 | I7: 1 | J7: =SUMIFS($D$4:$D$99,$B$4:$B$99,B7,$I$4:$I$99,"<="&I7) -> 95778 | K7: =IFERROR(J7/SUMIFS($C$4:$C$99,$B$4:$B$99,B7),0) -> 0.082786483
A8: Jan | B8: HR | C8: 60000 | D8: 64807 | E8: =D8-C8 -> 4807 | F8: =IFERROR(E8/C8,0) -> 0.080116667 | G8: Payroll | H8: CC-5000 | I8: 1 | J8: =SUMIFS($D$4:$D$99,$B$4:$B$99,B8,$I$4:$I$99,"<="&I8) -> 64807 | K8: =IFERROR(J8/SUMIFS($C$4:$C$99,$B$4:$B$99,B8),0) -> 0.088692637
A9: Jan | B9: Finance | C9: 70000 | D9: 72573 | E9: =D9-C9 -> 2573 | F9: =IFERROR(E9/C9,0) -> 0.036757143 | G9: Professional Services | H9: CC-6000 | I9: 1 | J9: =SUMIFS($D$4:$D$99,$B$4:$B$99,B9,$I$4:$I$99,"<="&I9) -> 72573 | K9: =IFERROR(J9/SUMIFS($C$4:$C$99,$B$4:$B$99,B9),0) -> 0.085132215
A10: Jan | B10: Customer Service | C10: 102000 | D10: 108157 | E10: =D10-C10 -> 6157 | F10: =IFERROR(E10/C10,0) -> 0.060362745 | G10: Payroll | H10: CC-7000 | I10: 1 | J10: =SUMIFS($D$4:$D$99,$B$4:$B$99,B10,$I$4:$I$99,"<="&I10) -> 108157 | K10: =IFERROR(J10/SUMIFS($C$4:$C$99,$B$4:$B$99,B10),0) -> 0.0994903
A11: Jan | B11: Executive | C11: 110000 | D11: 107881 | E11: =D11-C11 -> -2119 | F11: =IFERROR(E11/C11,0) -> -0.019263636 | G11: Payroll | H11: CC-8000 | I11: 1 | J11: =SUMIFS($D$4:$D$99,$B$4:$B$99,B11,$I$4:$I$99,"<="&I11) -> 107881 | K11: =IFERROR(J11/SUMIFS($C$4:$C$99,$B$4:$B$99,B11),0) -> 0.080532128
A12: Feb | B12: Sales | C12: 180486 | D12: 183849 | E12: =D12-C12 -> 3363 | F12: =IFERROR(E12/C12,0) -> 0.018633024 | G12: Payroll | H12: CC-1000 | I12: 2 | J12: =SUMIFS($D$4:$D$99,$B$4:$B$99,B12,$I$4:$I$99,"<="&I12) -> 357444 | K12: =IFERROR(J12/SUMIFS($C$4:$C$99,$B$4:$B$99,B12),0) -> 0.16306186
A13: Feb | B13: Marketing | C13: 150405 | D13: 147097 | E13: =D13-C13 -> -3308 | F13: =IFERROR(E13/C13,0) -> -0.02199395 | G13: Marketing Spend | H13: CC-2000 | I13: 2 | J13: =SUMIFS($D$4:$D$99,$B$4:$B$99,B13,$I$4:$I$99,"<="&I13) -> 312759 | K13: =IFERROR(J13/SUMIFS($C$4:$C$99,$B$4:$B$99,B13),0) -> 0.15911978
A14: Feb | B14: Operations | C14: 243095 | D14: 247231 | E14: =D14-C14 -> 4136 | F14: =IFERROR(E14/C14,0) -> 0.017013925 | G14: Payroll | H14: CC-3000 | I14: 2 | J14: =SUMIFS($D$4:$D$99,$B$4:$B$99,B14,$I$4:$I$99,"<="&I14) -> 480380 | K14: =IFERROR(J14/SUMIFS($C$4:$C$99,$B$4:$B$99,B14),0) -> 0.15334822
A15: Feb | B15: IT | C15: 95256 | D15: 93842 | E15: =D15-C15 -> -1414 | F15: =IFERROR(E15/C15,0) -> -0.014844209 | G15: Software & IT | H15: CC-4400 | I15: 2 | J15: =SUMIFS($D$4:$D$99,$B$4:$B$99,B15,$I$4:$I$99,"<="&I15) -> 189620 | K15: =IFERROR(J15/SUMIFS($C$4:$C$99,$B$4:$B$99,B15),0) -> 0.16389957
A16: Feb | B16: HR | C16: 60162 | D16: 57876 | E16: =D16-C16 -> -2286 | F16: =IFERROR(E16/C16,0) -> -0.037997407 | G16: Payroll | H16: CC-5000 | I16: 2 | J16: =SUMIFS($D$4:$D$99,$B$4:$B$99,B16,$I$4:$I$99,"<="&I16) -> 122683 | K16: =IFERROR(J16/SUMIFS($C$4:$C$99,$B$4:$B$99,B16),0) -> 0.16789974
A17: Feb | B17: Finance | C17: 70189 | D17: 67881 | E17: =D17-C17 -> -2308 | F17: =IFERROR(E17/C17,0) -> -0.032882645 | G17: Professional Services | H17: CC-6000 | I17: 2 | J17: =SUMIFS($D$4:$D$99,$B$4:$B$99,B17,$I$4:$I$99,"<="&I17) -> 140454 | K17: =IFERROR(J17/SUMIFS($C$4:$C$99,$B$4:$B$99,B17),0) -> 0.16476045
A18: Feb | B18: Customer Service | C18: 85230 | D18: 88901 | E18: =D18-C18 -> 3671 | F18: =IFERROR(E18/C18,0) -> 0.043071688 | G18: Payroll | H18: CC-7000 | I18: 2 | J18: =SUMIFS($D$4:$D$99,$B$4:$B$99,B18,$I$4:$I$99,"<="&I18) -> 197058 | K18: =IFERROR(J18/SUMIFS($C$4:$C$99,$B$4:$B$99,B18),0) -> 0.1812676
A19: Feb | B19: Executive | C19: 110297 | D19: 122565 | E19: =D19-C19 -> 12268 | F19: =IFERROR(E19/C19,0) -> 0.11122696 | G19: Payroll | H19: CC-8000 | I19: 2 | J19: =SUMIFS($D$4:$D$99,$B$4:$B$99,B19,$I$4:$I$99,"<="&I19) -> 230446 | K19: =IFERROR(J19/SUMIFS($C$4:$C$99,$B$4:$B$99,B19),0) -> 0.17202572 | L19: One-time expense pulled forward from a later month.
A20: Mar | B20: Sales | C20: 180972 | D20: 163316 | E20: =D20-C20 -> -17656 | F20: =IFERROR(E20/C20,0) -> -0.097562054 | G20: Payroll | H20: CC-1000 | I20: 3 | J20: =SUMIFS($D$4:$D$99,$B$4:$B$99,B20,$I$4:$I$99,"<="&I20) -> 520760 | K20: =IFERROR(J20/SUMIFS($C$4:$C$99,$B$4:$B$99,B20),0) -> 0.23756476
A21: Mar | B21: Marketing | C21: 150810 | D21: 170044 | E21: =D21-C21 -> 19234 | F21: =IFERROR(E21/C21,0) -> 0.12753796 | G21: Marketing Spend | H21: CC-2000 | I21: 3 | J21: =SUMIFS($D$4:$D$99,$B$4:$B$99,B21,$I$4:$I$99,"<="&I21) -> 482803 | K21: =IFERROR(J21/SUMIFS($C$4:$C$99,$B$4:$B$99,B21),0) -> 0.24563165 | L21: Overspend driven by higher contractor/vendor usage this month.
A22: Mar | B22: Operations | C22: 249721 | D22: 239214 | E22: =D22-C22 -> -10507 | F22: =IFERROR(E22/C22,0) -> -0.042074956 | G22: Payroll | H22: CC-3000 | I22: 3 | J22: =SUMIFS($D$4:$D$99,$B$4:$B$99,B22,$I$4:$I$99,"<="&I22) -> 719594 | K22: =IFERROR(J22/SUMIFS($C$4:$C$99,$B$4:$B$99,B22),0) -> 0.22971076
A23: Mar | B23: IT | C23: 95513 | D23: 95278 | E23: =D23-C23 -> -235 | F23: =IFERROR(E23/C23,0) -> -0.0024603981 | G23: Software & IT | H23: CC-4400 | I23: 3 | J23: =SUMIFS($D$4:$D$99,$B$4:$B$99,B23,$I$4:$I$99,"<="&I23) -> 284898 | K23: =IFERROR(J23/SUMIFS($C$4:$C$99,$B$4:$B$99,B23),0) -> 0.24625387
A24: Mar | B24: HR | C24: 60324 | D24: 62329 | E24: =D24-C24 -> 2005 | F24: =IFERROR(E24/C24,0) -> 0.033237186 | G24: Payroll | H24: CC-5000 | I24: 3 | J24: =SUMIFS($D$4:$D$99,$B$4:$B$99,B24,$I$4:$I$99,"<="&I24) -> 185012 | K24: =IFERROR(J24/SUMIFS($C$4:$C$99,$B$4:$B$99,B24),0) -> 0.25320108
A25: Mar | B25: Finance | C25: 70378 | D25: 67399 | E25: =D25-C25 -> -2979 | F25: =IFERROR(E25/C25,0) -> -0.042328569 | G25: Professional Services | H25: CC-6000 | I25: 3 | J25: =SUMIFS($D$4:$D$99,$B$4:$B$99,B25,$I$4:$I$99,"<="&I25) -> 207853 | K25: =IFERROR(J25/SUMIFS($C$4:$C$99,$B$4:$B$99,B25),0) -> 0.24382327
A26: Mar | B26: Customer Service | C26: 85459 | D26: 86678 | E26: =D26-C26 -> 1219 | F26: =IFERROR(E26/C26,0) -> 0.01426415 | G26: Payroll | H26: CC-7000 | I26: 3 | J26: =SUMIFS($D$4:$D$99,$B$4:$B$99,B26,$I$4:$I$99,"<="&I26) -> 283736 | K26: =IFERROR(J26/SUMIFS($C$4:$C$99,$B$4:$B$99,B26),0) -> 0.26100003
A27: Mar | B27: Executive | C27: 110594 | D27: 118429 | E27: =D27-C27 -> 7835 | F27: =IFERROR(E27/C27,0) -> 0.070844711 | G27: Payroll | H27: CC-8000 | I27: 3 | J27: =SUMIFS($D$4:$D$99,$B$4:$B$99,B27,$I$4:$I$99,"<="&I27) -> 348875 | K27: =IFERROR(J27/SUMIFS($C$4:$C$99,$B$4:$B$99,B27),0) -> 0.26043183
A28: Apr | B28: Sales | C28: 181458 | D28: 182830 | E28: =D28-C28 -> 1372 | F28: =IFERROR(E28/C28,0) -> 0.0075609783 | G28: Payroll | H28: CC-1000 | I28: 4 | J28: =SUMIFS($D$4:$D$99,$B$4:$B$99,B28,$I$4:$I$99,"<="&I28) -> 703590 | K28: =IFERROR(J28/SUMIFS($C$4:$C$99,$B$4:$B$99,B28),0) -> 0.32096971
A29: Apr | B29: Marketing | C29: 151215 | D29: 136719 | E29: =D29-C29 -> -14496 | F29: =IFERROR(E29/C29,0) -> -0.095863506 | G29: Marketing Spend | H29: CC-2000 | I29: 4 | J29: =SUMIFS($D$4:$D$99,$B$4:$B$99,B29,$I$4:$I$99,"<="&I29) -> 619522 | K29: =IFERROR(J29/SUMIFS($C$4:$C$99,$B$4:$B$99,B29),0) -> 0.31518903
A30: Apr | B30: Operations | C30: 253719 | D30: 246264 | E30: =D30-C30 -> -7455 | F30: =IFERROR(E30/C30,0) -> -0.0293829 | G30: Payroll | H30: CC-3000 | I30: 4 | J30: =SUMIFS($D$4:$D$99,$B$4:$B$99,B30,$I$4:$I$99,"<="&I30) -> 965858 | K30: =IFERROR(J30/SUMIFS($C$4:$C$99,$B$4:$B$99,B30),0) -> 0.30832383
A31: Apr | B31: IT | C31: 95770 | D31: 95488 | E31: =D31-C31 -> -282 | F31: =IFERROR(E31/C31,0) -> -0.0029445547 | G31: Software & IT | H31: CC-4400 | I31: 4 | J31: =SUMIFS($D$4:$D$99,$B$4:$B$99,B31,$I$4:$I$99,"<="&I31) -> 380386 | K31: =IFERROR(J31/SUMIFS($C$4:$C$99,$B$4:$B$99,B31),0) -> 0.32878969
A32: Apr | B32: HR | C32: 60486 | D32: 57969 | E32: =D32-C32 -> -2517 | F32: =IFERROR(E32/C32,0) -> -0.041612935 | G32: Payroll | H32: CC-5000 | I32: 4 | J32: =SUMIFS($D$4:$D$99,$B$4:$B$99,B32,$I$4:$I$99,"<="&I32) -> 242981 | K32: =IFERROR(J32/SUMIFS($C$4:$C$99,$B$4:$B$99,B32),0) -> 0.33253546
A33: Apr | B33: Finance | C33: 70567 | D33: 74755 | E33: =D33-C33 -> 4188 | F33: =IFERROR(E33/C33,0) -> 0.059347854 | G33: Professional Services | H33: CC-6000 | I33: 4 | J33: =SUMIFS($D$4:$D$99,$B$4:$B$99,B33,$I$4:$I$99,"<="&I33) -> 282608 | K33: =IFERROR(J33/SUMIFS($C$4:$C$99,$B$4:$B$99,B33),0) -> 0.3315151
... A36: May | B36: Sales | C36: 181944 | D36: 178760 | E36: =D36-C36 -> -3184 | F36: =IFERROR(E36/C36,0) -> -0.01749989 | G36: Payroll | H36: CC-1000 | I36: 5 | J36: =SUMIFS($D$4:$D$99,$B$4:$B$99,B36,$I$4:$I$99,"<="&I36) -> 882350 | K36: =IFERROR(J36/SUMIFS($C$4:$C$99,$B$4:$B$99,B36),0) -> 0.40251798
A37: May | B37: Marketing | C37: 151620 | D37: 172724 | E37: =D37-C37 -> 21104 | F37: =IFERROR(E37/C37,0) -> 0.13919008 | G37: Marketing Spend | H37: CC-2000 | I37: 5 | J37: =SUMIFS($D$4:$D$99,$B$4:$B$99,B37,$I$4:$I$99,"<="&I37) -> 792246 | K37: =IFERROR(J37/SUMIFS($C$4:$C$99,$B$4:$B$99,B37),0) -> 0.40306437 | L37: One-time expense pulled forward from a later month.
A38: May | B38: Operations | C38: 255732 | D38: 250461 | E38: =D38-C38 -> -5271 | F38: =IFERROR(E38/C38,0) -> -0.020611421 | G38: Payroll | H38: CC-3000 | I38: 5 | J38: =SUMIFS($D$4:$D$99,$B$4:$B$99,B38,$I$4:$I$99,"<="&I38) -> 1216319 | K38: =IFERROR(J38/SUMIFS($C$4:$C$99,$B$4:$B$99,B38),0) -> 0.38827667
A39: May | B39: IT | C39: 96026 | D39: 102622 | E39: =D39-C39 -> 6596 | F39: =IFERROR(E39/C39,0) -> 0.06868973 | G39: Software & IT | H39: CC-4400 | I39: 5 | J39: =SUMIFS($D$4:$D$99,$B$4:$B$99,B39,$I$4:$I$99,"<="&I39) -> 483008 | K39: =IFERROR(J39/SUMIFS($C$4:$C$99,$B$4:$B$99,B39),0) -> 0.41749184
A40: May | B40: HR | C40: 60648 | D40: 58527 | E40: =D40-C40 -> -2121 | F40: =IFERROR(E40/C40,0) -> -0.034972299 | G40: Payroll | H40: CC-5000 | I40: 5 | J40: =SUMIFS($D$4:$D$99,$B$4:$B$99,B40,$I$4:$I$99,"<="&I40) -> 301508 | K40: =IFERROR(J40/SUMIFS($C$4:$C$99,$B$4:$B$99,B40),0) -> 0.4126335
A41: May | B41: Finance | C41: 70756 | D41: 67950 | E41: =D41-C41 -> -2806 | F41: =IFERROR(E41/C41,0) -> -0.039657414 | G41: Professional Services | H41: CC-6000 | I41: 5 | J41: =SUMIFS($D$4:$D$99,$B$4:$B$99,B41,$I$4:$I$99,"<="&I41) -> 350558 | K41: =IFERROR(J41/SUMIFS($C$4:$C$99,$B$4:$B$99,B41),0) -> 0.41122427
A42: May | B42: Customer Service | C42: 85918 | D42: 79814 | E42: =D42-C42 -> -6104 | F42: =IFERROR(E42/C42,0) -> -0.071044484 | G42: Payroll | H42: CC-7000 | I42: 5 | J42: =SUMIFS($D$4:$D$99,$B$4:$B$99,B42,$I$4:$I$99,"<="&I42) -> 448258 | K42: =IFERROR(J42/SUMIFS($C$4:$C$99,$B$4:$B$99,B42),0) -> 0.41233876
A43: May | B43: Executive | C43: 111188 | D43: 105208 | E43: =D43-C43 -> -5980 | F43: =IFERROR(E43/C43,0) -> -0.053782782 | G43: Payroll | H43: CC-8000 | I43: 5 | J43: =SUMIFS($D$4:$D$99,$B$4:$B$99,B43,$I$4:$I$99,"<="&I43) -> 568615 | K43: =IFERROR(J43/SUMIFS($C$4:$C$99,$B$4:$B$99,B43),0) -> 0.42446562
...

Sheet Variance Report
A1: FY2027 Budget vs. Actual Variance Report
A2: All figures pull live from Revenue Detail and Expense Detail via SUMIF.
A4: Revenue Variance by Product Line
A5: Product Line | B5: Budgeted Revenue | C5: Actual Revenue | D5: Variance $ | E5: Variance %
A6: Apparel | B6: =SUMIF('Revenue Detail'!$C$4:$C$195,A6,'Revenue Detail'!$F$4:$F$195) -> 4845883 | C6: =SUMIF('Revenue Detail'!$C$4:$C$195,A6,'Revenue Detail'!$I$4:$I$195) -> 4995971.7 | D6: =C6-B6 -> 150088.61 | E6: =IFERROR(D6/B6,0) -> 0.030972396
A7: Home Goods | B7: =SUMIF('Revenue Detail'!$C$4:$C$195,A7,'Revenue Detail'!$F$4:$F$195) -> 4199798.7 | C7: =SUMIF('Revenue Detail'!$C$4:$C$195,A7,'Revenue Detail'!$I$4:$I$195) -> 4264274.9 | D7: =C7-B7 -> 64476.19 | E7: =IFERROR(D7/B7,0) -> 0.01535221
A8: Electronics | B8: =SUMIF('Revenue Detail'!$C$4:$C$195,A8,'Revenue Detail'!$F$4:$F$195) -> 5923115 | C8: =SUMIF('Revenue Detail'!$C$4:$C$195,A8,'Revenue Detail'!$I$4:$I$195) -> 6003090.7 | D8: =C8-B8 -> 79975.72 | E8: =IFERROR(D8/B8,0) -> 0.013502307
A9: Outdoor | B9: =SUMIF('Revenue Detail'!$C$4:$C$195,A9,'Revenue Detail'!$F$4:$F$195) -> 4092029.4 | C9: =SUMIF('Revenue Detail'!$C$4:$C$195,A9,'Revenue Detail'!$I$4:$I$195) -> 4105308.8 | D9: =C9-B9 -> 13279.46 | E9: =IFERROR(D9/B9,0) -> 0.0032452015
A10: Total Revenue | B10: =SUM(B6:B9) -> 19060826 | C10: =SUM(C6:C9) -> 19368646 | D10: =C10-B10 -> 307819.98 | E10: =IFERROR(D10/B10,0) -> 0.016149351
A12: Expense Variance by Department
A13: Department | B13: Budgeted Amount | C13: Actual Amount | D13: Variance $ | E13: Variance %
A14: Sales | B14: =SUMIF('Expense Detail'!$B$4:$B$99,A14,'Expense Detail'!$C$4:$C$99) -> 2192076 | C14: =SUMIF('Expense Detail'!$B$4:$B$99,A14,'Expense Detail'!$D$4:$D$99) -> 2172994 | D14: =C14-B14 -> -19082 | E14: =IFERROR(D14/B14,0) -> -0.0087049902
A15: Marketing | B15: =SUMIF('Expense Detail'!$B$4:$B$99,A15,'Expense Detail'!$C$4:$C$99) -> 1965557 | C15: =SUMIF('Expense Detail'!$B$4:$B$99,A15,'Expense Detail'!$D$4:$D$99) -> 2068173 | D15: =C15-B15 -> 102616 | E15: =IFERROR(D15/B15,0) -> 0.052207084
A16: Operations | B16: =SUMIF('Expense Detail'!$B$4:$B$99,A16,'Expense Detail'!$C$4:$C$99) -> 3132609 | C16: =SUMIF('Expense Detail'!$B$4:$B$99,A16,'Expense Detail'!$D$4:$D$99) -> 3242278 | D16: =C16-B16 -> 109669 | E16: =IFERROR(D16/B16,0) -> 0.035008838
A17: IT | B17: =SUMIF('Expense Detail'!$B$4:$B$99,A17,'Expense Detail'!$C$4:$C$99) -> 1156928 | C17: =SUMIF('Expense Detail'!$B$4:$B$99,A17,'Expense Detail'!$D$4:$D$99) -> 1175166 | D17: =C17-B17 -> 18238 | E17: =IFERROR(D17/B17,0) -> 0.015764162
A18: HR | B18: =SUMIF('Expense Detail'!$B$4:$B$99,A18,'Expense Detail'!$C$4:$C$99) -> 730692 | C18: =SUMIF('Expense Detail'!$B$4:$B$99,A18,'Expense Detail'!$D$4:$D$99) -> 714025 | D18: =C18-B18 -> -16667 | E18: =IFERROR(D18/B18,0) -> -0.022809884
A19: Finance | B19: =SUMIF('Expense Detail'!$B$4:$B$99,A19,'Expense Detail'!$C$4:$C$99) -> 852474 | C19: =SUMIF('Expense Detail'!$B$4:$B$99,A19,'Expense Detail'!$D$4:$D$99) -> 857492 | D19: =C19-B19 -> 5018 | E19: =IFERROR(D19/B19,0) -> 0.0058863965
A20: Customer Service | B20: =SUMIF('Expense Detail'!$B$4:$B$99,A20,'Expense Detail'!$C$4:$C$99) -> 1087111 | C20: =SUMIF('Expense Detail'!$B$4:$B$99,A20,'Expense Detail'!$D$4:$D$99) -> 1094062 | D20: =C20-B20 -> 6951 | E20: =IFERROR(D20/B20,0) -> 0.0063940113
A21: Executive | B21: =SUMIF('Expense Detail'!$B$4:$B$99,A21,'Expense Detail'!$C$4:$C$99) -> 1339602 | C21: =SUMIF('Expense Detail'!$B$4:$B$99,A21,'Expense Detail'!$D$4:$D$99) -> 1383220 | D21: =C21-B21 -> 43618 | E21: =IFERROR(D21/B21,0) -> 0.032560417
A22: Total Expense | B22: =SUM(B14:B21) -> 12457049 | C22: =SUM(C14:C21) -> 12707410 | D22: =C22-B22 -> 250361 | E22: =IFERROR(D22/B22,0) -> 0.020097938
A24: Net Operating Income Summary
A25: Budgeted Revenue | E25: =B10 -> 19060826
A26: Budgeted Expense | E26: =B22 -> 12457049
A27: Budgeted Net Operating Income | E27: =E25-E26 -> 6603777.1
A28: Actual Revenue | E28: =C10 -> 19368646
A29: Actual Expense | E29: =C22 -> 12707410
A30: Actual Net Operating Income | E30: =E28-E29 -> 6661236.1
A31: NOI Variance $ | E31: =E30-E27 -> 57458.98
A32: NOI Variance % | E32: =IFERROR(E31/E27,0) -> 0.0087009266

Sheet Cash Flow Forecast
A1: FY2027 Cash Flow Forecast — Scenario Planning
A2: Driven by the Active Planning Scenario on the Assumptions tab — change it there to re-forecast.
A3: Active Scenario: | C3: =Assumptions!$B$19 -> Likely Case
A4: Revenue Multiplier: | C4: =Assumptions!$B$26 -> 1
A5: Expense Multiplier: | C5: =Assumptions!$B$27 -> 1
A7: Month | B7: Beginning Cash | C7: Cash Receipts | D7: Operating Disbursements | E7: Capital Expenditures | F7: Debt Service | G7: Ending Cash Balance
A8: Jan | B8: =Assumptions!$D$15 -> 850000 | C8: =SUMIF('Revenue Detail'!$A$4:$A$195,A8,'Revenue Detail'!$F$4:$F$195)*Assumptions!$D$14*Assumptions!$B$26 -> 1159305.6 | D8: =SUMIF('Expense Detail'!$A$4:$A$99,A8,'Expense Detail'!$C$4:$C$99)*Assumptions!$B$27 -> 1008120 | E8: 15000 | F8: =Assumptions!$D$16 -> 15000 | G8: =B8+C8-D8-E8-F8 -> 971185.6
A9: Feb | B9: =G8 -> 971185.6 | C9: =SUMIF('Revenue Detail'!$A$4:$A$195,A9,'Revenue Detail'!$F$4:$F$195)*Assumptions!$D$14*Assumptions!$B$26 -> 1190555.3 | D9: =SUMIF('Expense Detail'!$A$4:$A$99,A9,'Expense Detail'!$C$4:$C$99)*Assumptions!$B$27 -> 995120 | E9: 15000 | F9: =Assumptions!$D$16 -> 15000 | G9: =B9+C9-D9-E9-F9 -> 1136620.9
A10: Mar | B10: =G9 -> 1136620.9 | C10: =SUMIF('Revenue Detail'!$A$4:$A$195,A10,'Revenue Detail'!$F$4:$F$195)*Assumptions!$D$14*Assumptions!$B$26 -> 1321441.2 | D10: =SUMIF('Expense Detail'!$A$4:$A$99,A10,'Expense Detail'!$C$4:$C$99)*Assumptions!$B$27 -> 1003771 | E10: 20000 | F10: =Assumptions!$D$16 -> 15000 | G10: =B10+C10-D10-E10-F10 -> 1419291.1
A11: Apr | B11: =G10 -> 1419291.1 | C11: =SUMIF('Revenue Detail'!$A$4:$A$195,A11,'Revenue Detail'!$F$4:$F$195)*Assumptions!$D$14*Assumptions!$B$26 -> 1395818.8 | D11: =SUMIF('Expense Detail'!$A$4:$A$99,A11,'Expense Detail'!$C$4:$C$99)*Assumptions!$B$27 -> 1009794 | E11: 150000 | F11: =Assumptions!$D$16 -> 15000 | G11: =B11+C11-D11-E11-F11 -> 1640315.9
A12: May | B12: =G11 -> 1640315.9 | C12: =SUMIF('Revenue Detail'!$A$4:$A$195,A12,'Revenue Detail'!$F$4:$F$195)*Assumptions!$D$14*Assumptions!$B$26 -> 1427871.7 | D12: =SUMIF('Expense Detail'!$A$4:$A$99,A12,'Expense Detail'!$C$4:$C$99)*Assumptions!$B$27 -> 1013832 | E12: 40000 | F12: =Assumptions!$D$16 -> 15000 | G12: =B12+C12-D12-E12-F12 -> 1999355.7
A13: Jun | B13: =G12 -> 1999355.7 | C13: =SUMIF('Revenue Detail'!$A$4:$A$195,A13,'Revenue Detail'!$F$4:$F$195)*Assumptions!$D$14*Assumptions!$B$26 -> 1503153.4 | D13: =SUMIF('Expense Detail'!$A$4:$A$99,A13,'Expense Detail'!$C$4:$C$99)*Assumptions!$B$27 -> 1019885 | E13: 20000 | F13: =Assumptions!$D$16 -> 15000 | G13: =B13+C13-D13-E13-F13 -> 2447624.1
A14: Jul | B14: =G13 -> 2447624.1 | C14: =SUMIF('Revenue Detail'!$A$4:$A$195,A14,'Revenue Detail'!$F$4:$F$195)*Assumptions!$D$14*Assumptions!$B$26 -> 1463613.5 | D14: =SUMIF('Expense Detail'!$A$4:$A$99,A14,'Expense Detail'!$C$4:$C$99)*Assumptions!$B$27 -> 1020590 | E14: 15000 | F14: =Assumptions!$D$16 -> 15000 | G14: =B14+C14-D14-E14-F14 -> 2860647.6
A15: Aug | B15: =G14 -> 2860647.6 | C15: =SUMIF('Revenue Detail'!$A$4:$A$195,A15,'Revenue Detail'!$F$4:$F$195)*Assumptions!$D$14*Assumptions!$B$26 -> 1524668.6 | D15: =SUMIF('Expense Detail'!$A$4:$A$99,A15,'Expense Detail'!$C$4:$C$99)*Assumptions!$B$27 -> 1025991 | E15: 15000 | F15: =Assumptions!$D$16 -> 15000 | G15: =B15+C15-D15-E15-F15 -> 3329325.1
A16: Sep | B16: =G15 -> 3329325.1 | C16: =SUMIF('Revenue Detail'!$A$4:$A$195,A16,'Revenue Detail'!$F$4:$F$195)*Assumptions!$D$14*Assumptions!$B$26 -> 1442009.1 | D16: =SUMIF('Expense Detail'!$A$4:$A$99,A16,'Expense Detail'!$C$4:$C$99)*Assumptions!$B$27 -> 1024665 | E16: 60000 | F16: =Assumptions!$D$16 -> 15000 | G16: =B16+C16-D16-E16-F16 -> 3671669.2
A17: Oct | B17: =G16 -> 3671669.2 | C17: =SUMIF('Revenue Detail'!$A$4:$A$195,A17,'Revenue Detail'!$F$4:$F$195)*Assumptions!$D$14*Assumptions!$B$26 -> 1619014.4 | D17: =SUMIF('Expense Detail'!$A$4:$A$99,A17,'Expense Detail'!$C$4:$C$99)*Assumptions!$B$27 -> 1035485 | E17: 90000 | F17: =Assumptions!$D$16 -> 15000 | G17: =B17+C17-D17-E17-F17 -> 4150198.6
A18: Nov | B18: =G17 -> 4150198.6 | C18: =SUMIF('Revenue Detail'!$A$4:$A$195,A18,'Revenue Detail'!$F$4:$F$195)*Assumptions!$D$14*Assumptions!$B$26 -> 1999584.4 | D18: =SUMIF('Expense Detail'!$A$4:$A$99,A18,'Expense Detail'!$C$4:$C$99)*Assumptions!$B$27 -> 1142619 | E18: 20000 | F18: =Assumptions!$D$16 -> 15000 | G18: =B18+C18-D18-E18-F18 -> 4972164
A19: Dec | B19: =G18 -> 4972164 | C19: =SUMIF('Revenue Detail'!$A$4:$A$195,A19,'Revenue Detail'!$F$4:$F$195)*Assumptions!$D$14*Assumptions!$B$26 -> 2251357 | D19: =SUMIF('Expense Detail'!$A$4:$A$99,A19,'Expense Detail'!$C$4:$C$99)*Assumptions!$B$27 -> 1157177 | E19: 15000 | F19: =Assumptions!$D$16 -> 15000 | G19: =B19+C19-D19-E19-F19 -> 6036344.1
A20: FY2027 TOTAL | C20: =SUM(C8:C19) -> 18298393 | D20: =SUM(D8:D19) -> 12457049 | E20: =SUM(E8:E19) -> 475000 | F20: =SUM(F8:F19) -> 180000 | G20: =G19 -> 6036344.1

Sheet Headcount Plan
A1: Headcount & Compensation Plan — FY2027
A2: Benefits Load % is applied on top of base salary to estimate fully-loaded monthly cost.
A4: Department | B4: Role | C4: Headcount | D4: Avg. Annual Salary | E4: Benefits Load % | F4: Fully-Loaded Monthly Cost
A5: Sales | B5: Sales Representative | C5: 12 | D5: 58000 | E5: 0.28 | F5: =C5*D5/12*(1+E5) -> 74240
A6: Sales | B6: Sales Manager | C6: 3 | D6: 85000 | E6: 0.28 | F6: =C6*D6/12*(1+E6) -> 27200
A7: Marketing | B7: Marketing Specialist | C7: 5 | D7: 62000 | E7: 0.28 | F7: =C7*D7/12*(1+E7) -> 33066.667
A8: Marketing | B8: Marketing Manager | C8: 2 | D8: 90000 | E8: 0.28 | F8: =C8*D8/12*(1+E8) -> 19200
A9: Operations | B9: Warehouse Associate | C9: 20 | D9: 42000 | E9: 0.28 | F9: =C9*D9/12*(1+E9) -> 89600
A10: Operations | B10: Operations Supervisor | C10: 4 | D10: 68000 | E10: 0.28 | F10: =C10*D10/12*(1+E10) -> 29013.333
A11: IT | B11: Software Engineer | C11: 6 | D11: 105000 | E11: 0.28 | F11: =C11*D11/12*(1+E11) -> 67200
A12: IT | B12: IT Support Specialist | C12: 3 | D12: 55000 | E12: 0.28 | F12: =C12*D12/12*(1+E12) -> 17600
A13: HR | B13: HR Generalist | C13: 3 | D13: 60000 | E13: 0.28 | F13: =C13*D13/12*(1+E13) -> 19200
A14: HR | B14: HR Director | C14: 1 | D14: 120000 | E14: 0.28 | F14: =C14*D14/12*(1+E14) -> 12800
A15: Finance | B15: Financial Analyst | C15: 4 | D15: 72000 | E15: 0.28 | F15: =C15*D15/12*(1+E15) -> 30720
A16: Finance | B16: Controller | C16: 1 | D16: 115000 | E16: 0.28 | F16: =C16*D16/12*(1+E16) -> 12266.667
... A20: Executive | B20: Chief Executive Officer | C20: 1 | D20: 250000 | E20: 0.28 | F20: =C20*D20/12*(1+E20) -> 26666.667
A21: TOTAL | C21: =SUM(C5:C20) -> 80 | D21: =AVERAGE(D5:D20) -> 91250 | F21: =SUM(F5:F20) -> 571413.33
A23: Note: fully-loaded monthly payroll cost above rolls up into the "Payroll" component of each department's line in Expense Detail; figures on that tab are entered independently by Finance each budget cycle.

Sheet Dashboard
A1: Meridian North Retail Co. — FY2027 Budget Dashboard
A2: All figures link live to Revenue Detail, Expense Detail, and the Variance Report.
A4: TOTAL REVENUE | C4: TOTAL EXPENSE | E4: NET OPERATING INCOME | G4: NOI VARIANCE
A5: ='Variance Report'!C10 -> 19368646 | C5: ='Variance Report'!C22 -> 12707410 | E5: ='Variance Report'!E30 -> 6661236.1 | G5: ='Variance Report'!E31 -> 57458.98
A6: ="Budget "&TEXT('Variance Report'!B10,"$#,##0")&" · "&TEXT(('Variance Report'!C10-'Variance Report'!B10)/'Variance Report'!B10,"+0.0%;-0.0%")&" vs. plan" -> Budget $19,060,826 · +1.6% vs. plan | C6: ="Budget "&TEXT('Variance Report'!B22,"$#,##0")&" · "&TEXT(('Variance Report'!C22-'Variance Report'!B22)/'Variance Report'!B22,"+0.0%;-0.0%")&" vs. plan" -> Budget $12,457,049 · +2.0% vs. plan | E6: ="Budget "&TEXT('Variance Report'!E27,"$#,##0")&" · "&TEXT('Variance Report'!E32,"+0.0%;-0.0%")&" vs. plan" -> Budget $6,603,777 · +0.9% vs. plan | G6: =IF('Variance Report'!E31>=0,"▲ ","▼ ")&TEXT('Variance Report'!E32,"+0.0%;-0.0%")&" vs. budgeted NOI" -> ▲ +0.9% vs. budgeted NOI
A8: Monthly Revenue: Budget vs. Actual | E8: Actual Expense by Department
A9: Month | B9: Budgeted Revenue | C9: Actual Revenue | D9: Trend | E9: Department | F9: Actual Expense | G9: Trend
A10: Jan | B10: =SUMIF('Revenue Detail'!$A$4:$A$195,A10,'Revenue Detail'!$F$4:$F$195) -> 1207610 | C10: =SUMIF('Revenue Detail'!$A$4:$A$195,A10,'Revenue Detail'!$I$4:$I$195) -> 1228606.7 | D10: =REPT("█",ROUND(C10/MAX($C$10:$C$21)*12,0)) -> ██████ | E10: Sales | F10: =SUMIF('Expense Detail'!$B$4:$B$99,E10,'Expense Detail'!$D$4:$D$99) -> 2172994 | G10: =REPT("█",ROUND(F10/MAX($F$10:$F$17)*12,0)) -> ████████
A11: Feb | B11: =SUMIF('Revenue Detail'!$A$4:$A$195,A11,'Revenue Detail'!$F$4:$F$195) -> 1240161.8 | C11: =SUMIF('Revenue Detail'!$A$4:$A$195,A11,'Revenue Detail'!$I$4:$I$195) -> 1267158 | D11: =REPT("█",ROUND(C11/MAX($C$10:$C$21)*12,0)) -> ██████ | E11: Marketing | F11: =SUMIF('Expense Detail'!$B$4:$B$99,E11,'Expense Detail'!$D$4:$D$99) -> 2068173 | G11: =REPT("█",ROUND(F11/MAX($F$10:$F$17)*12,0)) -> ████████
A12: Mar | B12: =SUMIF('Revenue Detail'!$A$4:$A$195,A12,'Revenue Detail'!$F$4:$F$195) -> 1376501.3 | C12: =SUMIF('Revenue Detail'!$A$4:$A$195,A12,'Revenue Detail'!$I$4:$I$195) -> 1426009.7 | D12: =REPT("█",ROUND(C12/MAX($C$10:$C$21)*12,0)) -> ███████ | E12: Operations | F12: =SUMIF('Expense Detail'!$B$4:$B$99,E12,'Expense Detail'!$D$4:$D$99) -> 3242278 | G12: =REPT("█",ROUND(F12/MAX($F$10:$F$17)*12,0)) -> ████████████
A13: Apr | B13: =SUMIF('Revenue Detail'!$A$4:$A$195,A13,'Revenue Detail'!$F$4:$F$195) -> 1453977.9 | C13: =SUMIF('Revenue Detail'!$A$4:$A$195,A13,'Revenue Detail'!$I$4:$I$195) -> 1461741.9 | D13: =REPT("█",ROUND(C13/MAX($C$10:$C$21)*12,0)) -> ███████ | E13: IT | F13: =SUMIF('Expense Detail'!$B$4:$B$99,E13,'Expense Detail'!$D$4:$D$99) -> 1175166 | G13: =REPT("█",ROUND(F13/MAX($F$10:$F$17)*12,0)) -> ████
A14: May | B14: =SUMIF('Revenue Detail'!$A$4:$A$195,A14,'Revenue Detail'!$F$4:$F$195) -> 1487366.4 | C14: =SUMIF('Revenue Detail'!$A$4:$A$195,A14,'Revenue Detail'!$I$4:$I$195) -> 1475662.3 | D14: =REPT("█",ROUND(C14/MAX($C$10:$C$21)*12,0)) -> ███████ | E14: HR | F14: =SUMIF('Expense Detail'!$B$4:$B$99,E14,'Expense Detail'!$D$4:$D$99) -> 714025 | G14: =REPT("█",ROUND(F14/MAX($F$10:$F$17)*12,0)) -> ███
A15: Jun | B15: =SUMIF('Revenue Detail'!$A$4:$A$195,A15,'Revenue Detail'!$F$4:$F$195) -> 1565784.8 | C15: =SUMIF('Revenue Detail'!$A$4:$A$195,A15,'Revenue Detail'!$I$4:$I$195) -> 1625131.8 | D15: =REPT("█",ROUND(C15/MAX($C$10:$C$21)*12,0)) -> ████████ | E15: Finance | F15: =SUMIF('Expense Detail'!$B$4:$B$99,E15,'Expense Detail'!$D$4:$D$99) -> 857492 | G15: =REPT("█",ROUND(F15/MAX($F$10:$F$17)*12,0)) -> ███
A16: Jul | B16: =SUMIF('Revenue Detail'!$A$4:$A$195,A16,'Revenue Detail'!$F$4:$F$195) -> 1524597.4 | C16: =SUMIF('Revenue Detail'!$A$4:$A$195,A16,'Revenue Detail'!$I$4:$I$195) -> 1549051.6 | D16: =REPT("█",ROUND(C16/MAX($C$10:$C$21)*12,0)) -> ████████ | E16: Customer Service | F16: =SUMIF('Expense Detail'!$B$4:$B$99,E16,'Expense Detail'!$D$4:$D$99) -> 1094062 | G16: =REPT("█",ROUND(F16/MAX($F$10:$F$17)*12,0)) -> ████
A17: Aug | B17: =SUMIF('Revenue Detail'!$A$4:$A$195,A17,'Revenue Detail'!$F$4:$F$195) -> 1588196.4 | C17: =SUMIF('Revenue Detail'!$A$4:$A$195,A17,'Revenue Detail'!$I$4:$I$195) -> 1608495.1 | D17: =REPT("█",ROUND(C17/MAX($C$10:$C$21)*12,0)) -> ████████ | E17: Executive | F17: =SUMIF('Expense Detail'!$B$4:$B$99,E17,'Expense Detail'!$D$4:$D$99) -> 1383220 | G17: =REPT("█",ROUND(F17/MAX($F$10:$F$17)*12,0)) -> █████
A18: Sep | B18: =SUMIF('Revenue Detail'!$A$4:$A$195,A18,'Revenue Detail'!$F$4:$F$195) -> 1502092.8 | C18: =SUMIF('Revenue Detail'!$A$4:$A$195,A18,'Revenue Detail'!$I$4:$I$195) -> 1506837.1 | D18: =REPT("█",ROUND(C18/MAX($C$10:$C$21)*12,0)) -> ████████
A19: Oct | B19: =SUMIF('Revenue Detail'!$A$4:$A$195,A19,'Revenue Detail'!$F$4:$F$195) -> 1686473.3 | C19: =SUMIF('Revenue Detail'!$A$4:$A$195,A19,'Revenue Detail'!$I$4:$I$195) -> 1710714.7 | D19: =REPT("█",ROUND(C19/MAX($C$10:$C$21)*12,0)) -> █████████
A20: Nov | B20: =SUMIF('Revenue Detail'!$A$4:$A$195,A20,'Revenue Detail'!$F$4:$F$195) -> 2082900.4 | C20: =SUMIF('Revenue Detail'!$A$4:$A$195,A20,'Revenue Detail'!$I$4:$I$195) -> 2106741.7 | D20: =REPT("█",ROUND(C20/MAX($C$10:$C$21)*12,0)) -> ███████████
A21: Dec | B21: =SUMIF('Revenue Detail'!$A$4:$A$195,A21,'Revenue Detail'!$F$4:$F$195) -> 2345163.6 | C21: =SUMIF('Revenue Detail'!$A$4:$A$195,A21,'Revenue Detail'!$I$4:$I$195) -> 2402495.6 | D21: =REPT("█",ROUND(C21/MAX($C$10:$C$21)*12,0)) -> ████████████

Sheet Assumptions
A1: Meridian North Retail Co. — FY2027 Budget Assumptions & Drivers
A2: Blue cells are editable inputs. Yellow fill marks key planning levers.
A4: Revenue Growth Assumptions (FY2027 vs. FY2026 Actual)
A5: Product Line | B5: FY2026 Actual Revenue | C5: FY2027 Growth Rate
A6: Apparel | B6: 4750000 | C6: 0.045
A7: Home Goods | B7: 3100000 | C7: 0.03
A8: Electronics | B8: 4200000 | C8: 0.06
A9: Outdoor | B9: 2650000 | C9: 0.05
A11: Cost & Operating Assumptions
A12: Expense Inflation Rate (FY2027 vs. FY2026) | D12: 0.032
A13: Effective Tax Rate | D13: 0.24
A14: Cash Collection Rate (% of monthly revenue collected same month) | D14: 0.96
A15: Starting Cash Balance (Jan 1, 2027) | D15: 850000
A16: Monthly Debt Service Payment | D16: 15000
A18: Scenario Planning
A19: Active Planning Scenario: | B19: Likely Case
A21: Scenario | B21: Revenue Multiplier | C21: Expense Multiplier
A22: Best Case | B22: 1.08 | C22: 0.97
A23: Likely Case | B23: 1 | C23: 1
A24: Worst Case | B24: 0.9 | C24: 1.05
A26: Selected Revenue Multiplier | B26: =INDEX($B$22:$B$24,MATCH($B$19,$A$22:$A$24,0)) -> 1
A27: Selected Expense Multiplier | B27: =INDEX($C$22:$C$24,MATCH($B$19,$A$22:$A$24,0)) -> 1

Sheet Budget Request Form
A1: FY2027 Department Budget Request Form
A3: Department: | B3: IT | F3: Cost Center Code: | G3: CC-4410
A4: Submitted By: | B4: J. Alvarez, IT Director | F4: Date Submitted: | G4: 2026-09-15
A6: Instructions: select your Department above, then enter a monthly dollar request for each expense category you need funded. Blue/yellow cells are editable; the FY2027 Total and grand total at the bottom recalculate automatically. Submit one form per department per budget cycle.
A8: Expense Category | B8: Jan | C8: Feb | D8: Mar | E8: Apr | F8: May | G8: Jun | H8: Jul | I8: Aug | J8: Sep | K8: Oct | L8: Nov | M8: Dec | N8: FY2027 Total | O8: Notes / Justification
A9: EXAMPLE — Software & IT | B9: 7200 | C9: 7200 | D9: 7400 | E9: 7400 | F9: 7600 | G9: 7600 | H9: 7800 | I9: 7800 | J9: 8000 | K9: 8000 | L9: 8200 | M9: 8600 | N9: =SUM(B9:M9) -> 92800 | O9: Includes SaaS license renewals (Q1) and two new laptop refresh batches (Q3/Q4).
N10: =SUM(B10:M10) -> 0
N11: =SUM(B11:M11) -> 0
N12: =SUM(B12:M12) -> 0
N13: =SUM(B13:M13) -> 0
N14: =SUM(B14:M14) -> 0
N15: =SUM(B15:M15) -> 0
A16: TOTAL DEPARTMENT REQUEST | B16: =SUM(B9:B15) -> 7200 | C16: =SUM(C9:C15) -> 7200 | D16: =SUM(D9:D15) -> 7400 | E16: =SUM(E9:E15) -> 7400 | F16: =SUM(F9:F15) -> 7600 | G16: =SUM(G9:G15) -> 7600 | H16: =SUM(H9:H15) -> 7800 | I16: =SUM(I9:I15) -> 7800 | ... N16: =SUM(N9:N15) -> 92800
